Workbook

Sheet Hướng dẫn
A1: KỊCH BẢN SALE TEST – GÓI STANDARD
A2: IACC Cloud · bản 28/10/2026 · viết theo docs/TONG-KET-LOGIC-STANDARD.md
A4: Mục đích | B4: Sale tự chạy thử phần mềm gói Standard theo từng tình huống khách trước khi đi bán, để nói đúng, demo trơn tru, biết chỗ nào chưa có.
A5: Link demo | B5: https://i-accounting.pages.dev (bản phát hành). Đăng nhập bằng email bất kỳ, mật khẩu từ 6 ký tự.
A6: Dữ liệu | B6: Dữ liệu giả, chỉ có số liệu tháng 7–10/2026. Mọi thao tác lưu trên trình duyệt của máy đang dùng; muốn làm lại từ đầu thì mở cửa sổ ẩn danh.
A7: Thứ tự | B7: Làm KB01 trước: tạo đơn vị hộ kinh doanh nhóm 2 tính theo % doanh thu. Các kịch bản sau làm trên đơn vị đó. KB07 cần đúng nhóm này.
A8: Cách ghi | B8: Sheet Kịch bản: làm từng bước, so với cột "Kết quả phải thấy", chọn Đạt, Lỗi hoặc Bỏ qua ở cột nền vàng. Lỗi thì ghi rõ thấy gì ở cột Ghi chú, gửi PhuongXT hoặc Trum.
A9: Câu nói khi demo | B9: Là gợi ý, nói theo cách của mình. Không hứa tính năng nằm ngoài cột "Kết quả phải thấy" và sheet Hỏi đáp khách.
A10: Câu chưa có lời đáp | B10: Ô "Hỏi Trum" ở sheet Hỏi đáp khách: chưa chốt, không tự trả lời khách.
A11: Tổng thời gian | B11: Khoảng 70 phút nếu chạy đủ 11 kịch bản. Đi gặp khách thì chọn kịch bản theo nỗi lo của khách, mỗi buổi 2–3 kịch bản.
A13: Người test
A14: Ngày test

Sheet Tổng hợp
A1: Mã | B1: Kịch bản | C1: Số bước | D1: Đạt | E1: Lỗi | F1: Bỏ qua | G1: Chưa test
A2: KB01 | B2: Chủ quán FABi lần đầu vào IACC: khởi tạo đơn vị | C2: =COUNTIFS('Kịch bản'!$A$2:$A$113,A2,'Kịch bản'!$B$2:$B$113,">0") | D2: =COUNTIFS('Kịch bản'!$A$2:$A$113,A2,'Kịch bản'!$F$2:$F$113,"Đạt") | E2: =COUNTIFS('Kịch bản'!$A$2:$A$113,A2,'Kịch bản'!$F$2:$F$113,"Lỗi") | F2: =COUNTIFS('Kịch bản'!$A$2:$A$113,A2,'Kịch bản'!$F$2:$F$113,"Bỏ qua") | G2: =C2-D2-E2-F2
A3: KB02 | B3: Tháng này quán lời hay lỗ | C3: =COUNTIFS('Kịch bản'!$A$2:$A$113,A3,'Kịch bản'!$B$2:$B$113,">0") | D3: =COUNTIFS('Kịch bản'!$A$2:$A$113,A3,'Kịch bản'!$F$2:$F$113,"Đạt") | E3: =COUNTIFS('Kịch bản'!$A$2:$A$113,A3,'Kịch bản'!$F$2:$F$113,"Lỗi") | F3: =COUNTIFS('Kịch bản'!$A$2:$A$113,A3,'Kịch bản'!$F$2:$F$113,"Bỏ qua") | G3: =C3-D3-E3-F3
A4: KB03 | B4: Quản lý tiền mặt, ngân hàng của các quán | C4: =COUNTIFS('Kịch bản'!$A$2:$A$113,A4,'Kịch bản'!$B$2:$B$113,">0") | D4: =COUNTIFS('Kịch bản'!$A$2:$A$113,A4,'Kịch bản'!$F$2:$F$113,"Đạt") | E4: =COUNTIFS('Kịch bản'!$A$2:$A$113,A4,'Kịch bản'!$F$2:$F$113,"Lỗi") | F4: =COUNTIFS('Kịch bản'!$A$2:$A$113,A4,'Kịch bản'!$F$2:$F$113,"Bỏ qua") | G4: =C4-D4-E4-F4
A5: KB04 | B5: Nhập hàng và nợ nhà cung cấp | C5: =COUNTIFS('Kịch bản'!$A$2:$A$113,A5,'Kịch bản'!$B$2:$B$113,">0") | D5: =COUNTIFS('Kịch bản'!$A$2:$A$113,A5,'Kịch bản'!$F$2:$F$113,"Đạt") | E5: =COUNTIFS('Kịch bản'!$A$2:$A$113,A5,'Kịch bản'!$F$2:$F$113,"Lỗi") | F5: =COUNTIFS('Kịch bản'!$A$2:$A$113,A5,'Kịch bản'!$F$2:$F$113,"Bỏ qua") | G5: =C5-D5-E5-F5
A6: KB05 | B6: Kiểm kê, biết hao hụt | C6: =COUNTIFS('Kịch bản'!$A$2:$A$113,A6,'Kịch bản'!$B$2:$B$113,">0") | D6: =COUNTIFS('Kịch bản'!$A$2:$A$113,A6,'Kịch bản'!$F$2:$F$113,"Đạt") | E6: =COUNTIFS('Kịch bản'!$A$2:$A$113,A6,'Kịch bản'!$F$2:$F$113,"Lỗi") | F6: =COUNTIFS('Kịch bản'!$A$2:$A$113,A6,'Kịch bản'!$F$2:$F$113,"Bỏ qua") | G6: =C6-D6-E6-F6
A7: KB06 | B7: Trả trước tiền nhà, tiền sửa quán | C7: =COUNTIFS('Kịch bản'!$A$2:$A$113,A7,'Kịch bản'!$B$2:$B$113,">0") | D7: =COUNTIFS('Kịch bản'!$A$2:$A$113,A7,'Kịch bản'!$F$2:$F$113,"Đạt") | E7: =COUNTIFS('Kịch bản'!$A$2:$A$113,A7,'Kịch bản'!$F$2:$F$113,"Lỗi") | F7: =COUNTIFS('Kịch bản'!$A$2:$A$113,A7,'Kịch bản'!$F$2:$F$113,"Bỏ qua") | G7: =C7-D7-E7-F7
A8: KB07 | B8: Hộ kinh doanh kê khai thuế | C8: =COUNTIFS('Kịch bản'!$A$2:$A$113,A8,'Kịch bản'!$B$2:$B$113,">0") | D8: =COUNTIFS('Kịch bản'!$A$2:$A$113,A8,'Kịch bản'!$F$2:$F$113,"Đạt") | E8: =COUNTIFS('Kịch bản'!$A$2:$A$113,A8,'Kịch bản'!$F$2:$F$113,"Lỗi") | F8: =COUNTIFS('Kịch bản'!$A$2:$A$113,A8,'Kịch bản'!$F$2:$F$113,"Bỏ qua") | G8: =C8-D8-E8-F8
A9: KB08 | B9: Cuối tháng khoá sổ | C9: =COUNTIFS('Kịch bản'!$A$2:$A$113,A9,'Kịch bản'!$B$2:$B$113,">0") | D9: =COUNTIFS('Kịch bản'!$A$2:$A$113,A9,'Kịch bản'!$F$2:$F$113,"Đạt") | E9: =COUNTIFS('Kịch bản'!$A$2:$A$113,A9,'Kịch bản'!$F$2:$F$113,"Lỗi") | F9: =COUNTIFS('Kịch bản'!$A$2:$A$113,A9,'Kịch bản'!$F$2:$F$113,"Bỏ qua") | G9: =C9-D9-E9-F9
A10: KB09 | B10: Chủ quán xem, lập phiếu trên điện thoại | C10: =COUNTIFS('Kịch bản'!$A$2:$A$113,A10,'Kịch bản'!$B$2:$B$113,">0") | D10: =COUNTIFS('Kịch bản'!$A$2:$A$113,A10,'Kịch bản'!$F$2:$F$113,"Đạt") | E10: =COUNTIFS('Kịch bản'!$A$2:$A$113,A10,'Kịch bản'!$F$2:$F$113,"Lỗi") | F10: =COUNTIFS('Kịch bản'!$A$2:$A$113,A10,'Kịch bản'!$F$2:$F$113,"Bỏ qua") | G10: =C10-D10-E10-F10
A11: KB10 | B11: Báo cáo cho chủ quán | C11: =COUNTIFS('Kịch bản'!$A$2:$A$113,A11,'Kịch bản'!$B$2:$B$113,">0") | D11: =COUNTIFS('Kịch bản'!$A$2:$A$113,A11,'Kịch bản'!$F$2:$F$113,"Đạt") | E11: =COUNTIFS('Kịch bản'!$A$2:$A$113,A11,'Kịch bản'!$F$2:$F$113,"Lỗi") | F11: =COUNTIFS('Kịch bản'!$A$2:$A$113,A11,'Kịch bản'!$F$2:$F$113,"Bỏ qua") | G11: =C11-D11-E11-F11
A12: KB11 | B12: Khách hỏi giá, gói | C12: =COUNTIFS('Kịch bản'!$A$2:$A$113,A12,'Kịch bản'!$B$2:$B$113,">0") | D12: =COUNTIFS('Kịch bản'!$A$2:$A$113,A12,'Kịch bản'!$F$2:$F$113,"Đạt") | E12: =COUNTIFS('Kịch bản'!$A$2:$A$113,A12,'Kịch bản'!$F$2:$F$113,"Lỗi") | F12: =COUNTIFS('Kịch bản'!$A$2:$A$113,A12,'Kịch bản'!$F$2:$F$113,"Bỏ qua") | G12: =C12-D12-E12-F12
B13: Cộng | C13: =SUM(C2:C12) | D13: =SUM(D2:D12) | E13: =SUM(E2:E12) | F13: =SUM(F2:F12) | G13: =SUM(G2:G12)

Sheet Kịch bản
A1: Mã | B1: Bước | C1: Thao tác của sale | D1: Câu nói khi demo | E1: Kết quả phải thấy | F1: Kết quả | G1: Ghi chú của sale
A2: KB01 | B2: Chủ quán FABi lần đầu vào IACC: khởi tạo đơn vị · 10 phút
B3: Khách | C3: Chủ hộ kinh doanh có 2–4 quán đang bán bằng FABi, chưa dùng phần mềm kế toán
B4: Mục tiêu | C4: Khách thấy chỉ mất vài phút là có sổ sách, dữ liệu FABi tự về
B5: Chuẩn bị | C5: Trình duyệt chưa có dữ liệu cũ của bản demo (mở cửa sổ ẩn danh cho chắc)
A6: KB01 | B6: 1 | C6: Mở https://i-accounting.pages.dev, đăng nhập bằng email bất kỳ, mật khẩu từ 6 ký tự | D6: Anh chị đang bán bằng FABi, kế toán nối thẳng từ đó, không phải nhập lại. | E6: Vào màn chọn đơn vị kế toán. Mỗi thẻ đơn vị ghi mã số thuế, chế độ, số điểm bán, kỳ đang mở
A7: KB01 | B7: 2 | C7: Bấm "Thử mở từ FABi" | D7: Đây là lúc anh chị bấm từ FABi sang IACC. | E7: Màn chào hiện số liệu lấy từ FABi: thương hiệu, cửa hàng, kênh bán, món
A8: KB01 | B8: 3 | C8: Bấm tiếp sang màn giới thiệu giao diện | D8: Trang chủ có 5 vùng chính, em chỉ nhanh từng vùng. | E8: Ảnh trang chủ đánh số 1–5
A9: KB01 | B9: 4 | C9: Ở màn chọn cửa hàng dùng thử: bỏ chọn hết cửa hàng | D9: Anh chị chọn quán nào đưa lên sổ trước cũng được. | E9: Mặc định chọn hết. Bỏ hết thì không đi tiếp được, phải chọn ít nhất 1 cửa hàng
A10: KB01 | B10: 5 | C10: Chọn lại cửa hàng, bấm Dùng thử | E10: Vào phần mềm. Popup khởi tạo 3 bước hiện đè lên, không đóng được. Thanh trên có chip "Dùng thử · còn 30 ngày"
A11: KB01 | B11: 6 | C11: Bước 1: chọn Hộ kinh doanh, xem nhóm hệ thống gợi ý | D11: Hệ thống tự gợi ý nhóm thuế theo doanh thu FABi 12 tháng, anh chị không phải tự tính. | E11: Có nhóm gợi ý theo doanh thu FABi. Bảng 4 nhóm: dưới 1 tỷ, 1 đến dưới 3 tỷ, 3 đến dưới 50 tỷ, từ 50 tỷ
A12: KB01 | B12: 7 | C12: Chọn nhóm 3 | D12: Nhóm 3 trở lên tính thuế theo lợi nhuận. Phần kê khai cho nhóm này sẽ có ở gói sau, phần quản lý vẫn dùng đủ. | E12: Hiện cảnh báo kê khai thuế chưa có ở gói Standard
A13: KB01 | B13: 8 | C13: Chọn nhóm 2, cách tính TNCN theo % doanh thu (để làm tiếp KB07) | E13: Nhóm 2 cho chọn 2 cách: theo % doanh thu hoặc theo lợi nhuận 15%. Chọn theo % doanh thu thì hết cảnh báo
A14: KB01 | B14: 9 | C14: Bước 2: nhập mã số thuế, bấm Tra cứu; chọn ngày đầu năm tài chính 01/01 | D14: Gõ mã số thuế là hệ thống điền tên, địa chỉ. | E14: Tên, địa chỉ tự điền. Hộ kinh doanh không bắt buộc mã số thuế. Ngày đầu năm chọn được 01/01, 01/04, 01/07, 01/10
A15: KB01 | B15: 10 | C15: Bước 3: thử đi tiếp khi chưa chọn cửa hàng chính | E15: Không đi tiếp được: hộ kinh doanh bắt buộc chọn cửa hàng chính
A16: KB01 | B16: 11 | C16: Chọn cửa hàng chính; chọn kênh online và sàn đã khấu trừ thuế (GrabFood, ShopeeFood) | D16: Sàn nào đã khấu trừ thuế thay anh chị thì đánh dấu ở đây. | E16: Lưu được lựa chọn cửa hàng chính, kênh, sàn
A17: KB01 | B17: 12 | C17: Xem phần Lấy dữ liệu FABi, bấm "Bắt đầu làm việc" | D17: Danh mục món, doanh thu từng đơn, thu chi đều tự về. | E17: Danh sách 4 việc kèm trạng thái: danh mục món và kênh, doanh thu, thu chi, ghi sổ. Bấm xong thì sang màn Danh mục
A18: KB02 | B18: Tháng này quán lời hay lỗ · 7 phút
B19: Khách | C19: Chủ quán chỉ muốn biết mỗi tháng lời bao nhiêu, chi vào đâu
B20: Mục tiêu | C20: Khách thấy lãi lỗ hiện ngay trên trang chủ, bấm vào là ra chi tiết
B21: Chuẩn bị | C21: Đã đăng nhập, đang ở đơn vị gói Standard
A22: KB02 | B22: 1 | C22: Bấm logo về Tổng quan, chọn Năm 2026, Tháng 10 | D22: Mở máy lên là thấy ngay tháng này lời bao nhiêu. | E22: Khối Kết quả kinh doanh: Doanh thu thuần, Chi phí NVL, Chi phí hoạt động, Chi phí phân bổ, Lợi nhuận, Biên lợi nhuận
A23: KB02 | B23: 2 | C23: Lấy máy tính cộng trừ: Doanh thu thuần − Chi phí NVL − Chi phí hoạt động − Chi phí phân bổ | E23: Bằng đúng số Lợi nhuận trên màn. Biên lợi nhuận = Lợi nhuận / Doanh thu
A24: KB02 | B24: 3 | C24: Đổi cửa hàng trên thanh trên: Tất cả cửa hàng → một cửa hàng | D24: Xem từng quán hay gộp cả chuỗi đều được. | E24: Số liệu đổi theo cửa hàng đang chọn
A25: KB02 | B25: 4 | C25: Bấm dòng Doanh thu thuần | E25: Mở Báo cáo kết quả kinh doanh, doanh thu khớp số trên trang chủ
A26: KB02 | B26: 5 | C26: Quay lại, bấm Chi phí NVL | D26: Giá vốn món lấy theo iPOS Inventory, hoặc nhập tay giá thành món, hoặc cộng phiếu nhập. Mỗi quán chọn một cách. | E26: Màn Chi phí NVL: bảng cửa hàng, cách tính, doanh thu, NVL, tỷ lệ
A27: KB02 | B27: 6 | C27: Quay lại, bấm Chi phí hoạt động; bấm một dòng lý do, bấm một số phiếu | D27: Mọi khoản chi gom theo lý do: điện nước, lương, thuê nhà… | E27: Mỗi lý do một dòng: số phiếu, tiền mặt, ngân hàng, % trên tổng. Bấm dòng xổ danh sách phiếu, bấm số phiếu mở phiếu
A28: KB02 | B28: 7 | C28: Xem biểu đồ hiệu quả 13 tháng | E28: Biểu đồ đủ 13 tháng. Lưu ý: tháng 7–10/2026 là số tính thật, các tháng trước là số mẫu
A29: KB03 | B29: Quản lý tiền mặt, ngân hàng của các quán · 8 phút
B30: Khách | C30: Chủ quán lo thất thoát tiền két, muốn biết tiền ở đâu
B31: Mục tiêu | C31: Khách thấy tiền FABi tự về quỹ, chi tiền là vào lãi lỗ ngay
B32: Chuẩn bị | C32: Đang xem "Tất cả cửa hàng" trên thanh trên
A33: KB03 | B33: 1 | C33: Trang chủ, xem khối Quỹ tiền | D33: Tiền trong két, trong tài khoản của từng quán, nằm một chỗ. | E33: Tồn quỹ, thu, chi trong tháng; vòng tròn cơ cấu quỹ
A34: KB03 | B34: 2 | C34: Bấm một quỹ trên vòng tròn | E34: Tồn đầu + Thu − Chi = Tồn cuối; số dư từng ngày; 3 giao dịch gần nhất; link Lịch sử thu chi
A35: KB03 | B35: 3 | C35: Bấm Lịch sử thu chi, bấm một giao dịch | D35: Đơn bán trên FABi tự thành phiếu thu, không ai nhập lại. | E35: Giao dịch gom theo ngày kèm số dư cuối ngày, nhãn FABi POS hoặc Thủ công. Bấm giao dịch mở chứng từ gốc
A36: KB03 | B36: 4 | C36: Về trang chủ, bấm thao tác nhanh Chi tiền | D36: Lập phiếu phải chọn quán để chi phí không lẫn giữa các quán. | E36: Hiện hộp chọn cửa hàng trước khi lập phiếu
A37: KB03 | B37: 5 | C37: Chọn cửa hàng. Lập phiếu chi tiền mặt, lý do điện nước (lý do là chi phí), số tiền 2.500.000, lưu | D37: Chi xong là vào lãi lỗ luôn. | E37: Có ô Tháng ghi nhận chi phí. Lưu được, số phiếu dạng PC2610-xxxx
A38: KB03 | B38: 6 | C38: Về trang chủ, xem cùng cửa hàng, tháng 10/2026 | E38: Chi phí hoạt động tăng 2.500.000, tồn quỹ tiền mặt giảm 2.500.000
A39: KB03 | B39: 7 | C39: Lập phiếu thu, lý do thu nợ, để trống Đối tượng, lưu | E39: Báo bắt buộc chọn Đối tượng
A40: KB03 | B40: 8 | C40: Mở Danh mục › Quỹ tiền | D40: Mỗi phương thức thanh toán trên FABi gắn vào một quỹ, tiền tự về đúng chỗ. | E40: Có cột Số dư ban đầu. Mỗi quỹ gắn phương thức thanh toán của từng cửa hàng
...

Sheet Hỏi đáp khách
A1: Khách hỏi | B1: Trả lời gợi ý | C1: Mở màn nào để chỉ | D1: Hỏi Trum
A2: Có phải nhập lại doanh thu từ FABi không? | B2: Không. Mỗi hoá đơn FABi tự thành một chứng từ Xuất bán POS. Thu chi FABi tự thành phiếu thu vào quỹ đã gắn với phương thức thanh toán. | C2: Bán hàng › Xuất bán POS; Trang chủ › Lịch sử thu chi
A3: Dùng có mất tiền không? | B3: Gói Standard miễn phí, không giới hạn số cửa hàng. Plus, Pro sắp ra mắt. | C3: Hệ thống › Gói thuê bao | D3: Thanh trên ghi "Dùng thử · còn 30 ngày". Hết 30 ngày thì sao, giá Plus, Pro: hỏi Trum trước khi trả lời
A4: Hộ kinh doanh có làm tờ khai thuế trên đây được không? | B4: Nhóm 1, hoặc nhóm 2 tính theo % doanh thu: được, lập tờ khai, bảng kê 01/BK-STK, tải XML. Nhóm 3, 4, hoặc nhóm 2 tính theo lợi nhuận: gói Standard chưa có kê khai, phần quản lý vẫn dùng đủ. | C4: Kê khai thuế
A5: Công ty (doanh nghiệp) dùng được không? | B5: Được. Chạy TT58, thuế GTGT, TNDN tính theo % doanh thu. Không ghi sổ Nợ/Có. Sổ theo chế độ là S1-DNSN. | C5: Hệ thống › Thông tin đơn vị; Báo cáo
A6: Có ghi sổ Nợ/Có, bảng cân đối, báo cáo tài chính không? | B6: Gói Standard không có. Đây là gói quản lý lãi lỗ, tiền, kho, thuế khoán. | D6: Gói nào có, khi nào có: hỏi Trum
A7: Có xuất hoá đơn điện tử không? | B7: Gói Standard không có hoá đơn điện tử, bán hàng ngoài POS, hàng bán trả lại, công nợ khách hàng.
A8: Nhiều người cùng dùng, phân quyền được không? | B8: Gói Standard không có màn Người dùng, Vai trò và phân quyền.
A9: Lãi lỗ tính thế nào? | B9: Lợi nhuận = Doanh thu thuần − Chi phí NVL − Chi phí hoạt động − Chi phí phân bổ. | C9: Trang chủ › Kết quả kinh doanh
A10: Giá vốn món ăn lấy ở đâu? | B10: Ba cách, mỗi cửa hàng chọn một: theo iPOS Inventory (mặc định), nhập tay giá thành món, theo phiếu nhập. Đổi cách chỉ áp dụng từ tháng chưa khoá sổ. | C10: Danh mục › Cửa hàng; Trang chủ › Chi phí NVL
A11: Kho có tính ra tiền tồn kho không? | B11: Không. Kiểm kê, xuất nhập tồn chỉ theo số lượng. Mỗi cửa hàng một kho, không thêm kho. | C11: Kiểm kê; Báo cáo › Xuất nhập tồn
A12: Tiền GrabFood, ShopeeFood về quỹ nào? | B12: Phương thức app giao đồ ăn mặc định chưa gắn quỹ. Gắn ở Danh mục › Quỹ tiền. Chưa gắn thì phiếu chờ, chưa vào sổ. | C12: Danh mục › Quỹ tiền
A13: Có dùng trên điện thoại được không? | B13: Được: trang chủ, lập phiếu thu chi, mua hàng, kiểm kê, xem phiếu, báo cáo. Điện thoại không xuất Excel, không in phiếu. | C13: Mở link trên điện thoại
A14: Lỡ ai sửa số tháng trước thì sao? | B14: Khoá sổ theo tháng, từng cửa hàng. Tháng đã khoá chỉ xem. Mở khoá phải ghi lý do, chỉ mở được tháng khoá gần nhất, có lịch sử. | C14: Hệ thống › Khoá sổ
A15: Đính kèm ảnh hoá đơn vào phiếu được không? | B15: Gói Standard chưa có đính kèm trên phiếu.
A16: Số liệu trước khi dùng phần mềm đưa vào thế nào? | B16: Doanh thu FABi lấy từ ngày đầu năm tài chính. Số dư quỹ khai ở Danh mục › Quỹ tiền. Chi phí trả trước còn dư lập thẻ dư đầu kỳ. | C16: Danh mục › Quỹ tiền; Chi phí phân bổ
A17: Dữ liệu lưu ở đâu, có an toàn không? | D17: Bản demo là dữ liệu giả, chưa có máy chủ. Câu hỏi về lưu trữ, bảo mật: hỏi Trum, không tự trả lời
