Workbook

Sheet Tổng hợp
A1: Test case gói Standard – IACC Cloud
A2: Web dựa trên docs/TONG-KET-LOGIC-STANDARD.md và danh sách màn trong src/app/registry.ts; App dựa trên src/ui/mobile/. Số liệu tự đếm từ hai sheet Web, App.
A4: Web
A5: Phân hệ | B5: Tổng | C5: Đạt | D5: Lỗi | E5: Bỏ qua | F5: Chưa test | G5: % Đã test
A6: Khung app | B6: =COUNTIF(Web!$A$2:$A$155,A6) -> 14 | C6: =COUNTIFS(Web!$A$2:$A$155,$A6,Web!$G$2:$G$155,"Đạt") -> 0 | D6: =COUNTIFS(Web!$A$2:$A$155,$A6,Web!$G$2:$G$155,"Lỗi") -> 0 | E6: =COUNTIFS(Web!$A$2:$A$155,$A6,Web!$G$2:$G$155,"Bỏ qua") -> 0 | F6: =COUNTIFS(Web!$A$2:$A$155,$A6,Web!$G$2:$G$155,"Chưa test") -> 14 | G6: =IF(B6=0,0,(C6+D6+E6)/B6) -> 0
A7: Đăng nhập, khởi tạo | B7: =COUNTIF(Web!$A$2:$A$155,A7) -> 12 | C7: =COUNTIFS(Web!$A$2:$A$155,$A7,Web!$G$2:$G$155,"Đạt") -> 0 | D7: =COUNTIFS(Web!$A$2:$A$155,$A7,Web!$G$2:$G$155,"Lỗi") -> 0 | E7: =COUNTIFS(Web!$A$2:$A$155,$A7,Web!$G$2:$G$155,"Bỏ qua") -> 0 | F7: =COUNTIFS(Web!$A$2:$A$155,$A7,Web!$G$2:$G$155,"Chưa test") -> 12 | G7: =IF(B7=0,0,(C7+D7+E7)/B7) -> 0
A8: Trang chủ | B8: =COUNTIF(Web!$A$2:$A$155,A8) -> 22 | C8: =COUNTIFS(Web!$A$2:$A$155,$A8,Web!$G$2:$G$155,"Đạt") -> 0 | D8: =COUNTIFS(Web!$A$2:$A$155,$A8,Web!$G$2:$G$155,"Lỗi") -> 0 | E8: =COUNTIFS(Web!$A$2:$A$155,$A8,Web!$G$2:$G$155,"Bỏ qua") -> 0 | F8: =COUNTIFS(Web!$A$2:$A$155,$A8,Web!$G$2:$G$155,"Chưa test") -> 22 | G8: =IF(B8=0,0,(C8+D8+E8)/B8) -> 0
A9: Danh mục | B9: =COUNTIF(Web!$A$2:$A$155,A9) -> 16 | C9: =COUNTIFS(Web!$A$2:$A$155,$A9,Web!$G$2:$G$155,"Đạt") -> 0 | D9: =COUNTIFS(Web!$A$2:$A$155,$A9,Web!$G$2:$G$155,"Lỗi") -> 0 | E9: =COUNTIFS(Web!$A$2:$A$155,$A9,Web!$G$2:$G$155,"Bỏ qua") -> 0 | F9: =COUNTIFS(Web!$A$2:$A$155,$A9,Web!$G$2:$G$155,"Chưa test") -> 16 | G9: =IF(B9=0,0,(C9+D9+E9)/B9) -> 0
A10: Thu chi | B10: =COUNTIF(Web!$A$2:$A$155,A10) -> 19 | C10: =COUNTIFS(Web!$A$2:$A$155,$A10,Web!$G$2:$G$155,"Đạt") -> 0 | D10: =COUNTIFS(Web!$A$2:$A$155,$A10,Web!$G$2:$G$155,"Lỗi") -> 0 | E10: =COUNTIFS(Web!$A$2:$A$155,$A10,Web!$G$2:$G$155,"Bỏ qua") -> 0 | F10: =COUNTIFS(Web!$A$2:$A$155,$A10,Web!$G$2:$G$155,"Chưa test") -> 19 | G10: =IF(B10=0,0,(C10+D10+E10)/B10) -> 0
A11: Kế toán bán hàng | B11: =COUNTIF(Web!$A$2:$A$155,A11) -> 9 | C11: =COUNTIFS(Web!$A$2:$A$155,$A11,Web!$G$2:$G$155,"Đạt") -> 0 | D11: =COUNTIFS(Web!$A$2:$A$155,$A11,Web!$G$2:$G$155,"Lỗi") -> 0 | E11: =COUNTIFS(Web!$A$2:$A$155,$A11,Web!$G$2:$G$155,"Bỏ qua") -> 0 | F11: =COUNTIFS(Web!$A$2:$A$155,$A11,Web!$G$2:$G$155,"Chưa test") -> 9 | G11: =IF(B11=0,0,(C11+D11+E11)/B11) -> 0
A12: Kế toán mua hàng | B12: =COUNTIF(Web!$A$2:$A$155,A12) -> 13 | C12: =COUNTIFS(Web!$A$2:$A$155,$A12,Web!$G$2:$G$155,"Đạt") -> 0 | D12: =COUNTIFS(Web!$A$2:$A$155,$A12,Web!$G$2:$G$155,"Lỗi") -> 2 | E12: =COUNTIFS(Web!$A$2:$A$155,$A12,Web!$G$2:$G$155,"Bỏ qua") -> 0 | F12: =COUNTIFS(Web!$A$2:$A$155,$A12,Web!$G$2:$G$155,"Chưa test") -> 0 | G12: =IF(B12=0,0,(C12+D12+E12)/B12) -> 0.15384615
A13: Kiểm kê | B13: =COUNTIF(Web!$A$2:$A$155,A13) -> 11 | C13: =COUNTIFS(Web!$A$2:$A$155,$A13,Web!$G$2:$G$155,"Đạt") -> 0 | D13: =COUNTIFS(Web!$A$2:$A$155,$A13,Web!$G$2:$G$155,"Lỗi") -> 0 | E13: =COUNTIFS(Web!$A$2:$A$155,$A13,Web!$G$2:$G$155,"Bỏ qua") -> 0 | F13: =COUNTIFS(Web!$A$2:$A$155,$A13,Web!$G$2:$G$155,"Chưa test") -> 11 | G13: =IF(B13=0,0,(C13+D13+E13)/B13) -> 0
A14: Chi phí phân bổ | B14: =COUNTIF(Web!$A$2:$A$155,A14) -> 7 | C14: =COUNTIFS(Web!$A$2:$A$155,$A14,Web!$G$2:$G$155,"Đạt") -> 0 | D14: =COUNTIFS(Web!$A$2:$A$155,$A14,Web!$G$2:$G$155,"Lỗi") -> 0 | E14: =COUNTIFS(Web!$A$2:$A$155,$A14,Web!$G$2:$G$155,"Bỏ qua") -> 0 | F14: =COUNTIFS(Web!$A$2:$A$155,$A14,Web!$G$2:$G$155,"Chưa test") -> 7 | G14: =IF(B14=0,0,(C14+D14+E14)/B14) -> 0
A15: Kê khai thuế | B15: =COUNTIF(Web!$A$2:$A$155,A15) -> 6 | C15: =COUNTIFS(Web!$A$2:$A$155,$A15,Web!$G$2:$G$155,"Đạt") -> 0 | D15: =COUNTIFS(Web!$A$2:$A$155,$A15,Web!$G$2:$G$155,"Lỗi") -> 0 | E15: =COUNTIFS(Web!$A$2:$A$155,$A15,Web!$G$2:$G$155,"Bỏ qua") -> 0 | F15: =COUNTIFS(Web!$A$2:$A$155,$A15,Web!$G$2:$G$155,"Chưa test") -> 6 | G15: =IF(B15=0,0,(C15+D15+E15)/B15) -> 0
A16: Báo cáo | B16: =COUNTIF(Web!$A$2:$A$155,A16) -> 11 | C16: =COUNTIFS(Web!$A$2:$A$155,$A16,Web!$G$2:$G$155,"Đạt") -> 0 | D16: =COUNTIFS(Web!$A$2:$A$155,$A16,Web!$G$2:$G$155,"Lỗi") -> 0 | E16: =COUNTIFS(Web!$A$2:$A$155,$A16,Web!$G$2:$G$155,"Bỏ qua") -> 0 | F16: =COUNTIFS(Web!$A$2:$A$155,$A16,Web!$G$2:$G$155,"Chưa test") -> 11 | G16: =IF(B16=0,0,(C16+D16+E16)/B16) -> 0
A17: Hệ thống | B17: =COUNTIF(Web!$A$2:$A$155,A17) -> 12 | C17: =COUNTIFS(Web!$A$2:$A$155,$A17,Web!$G$2:$G$155,"Đạt") -> 0 | D17: =COUNTIFS(Web!$A$2:$A$155,$A17,Web!$G$2:$G$155,"Lỗi") -> 0 | E17: =COUNTIFS(Web!$A$2:$A$155,$A17,Web!$G$2:$G$155,"Bỏ qua") -> 0 | F17: =COUNTIFS(Web!$A$2:$A$155,$A17,Web!$G$2:$G$155,"Chưa test") -> 12 | G17: =IF(B17=0,0,(C17+D17+E17)/B17) -> 0
A18: Doanh nghiệp TT58 | B18: =COUNTIF(Web!$A$2:$A$155,A18) -> 2 | C18: =COUNTIFS(Web!$A$2:$A$155,$A18,Web!$G$2:$G$155,"Đạt") -> 0 | D18: =COUNTIFS(Web!$A$2:$A$155,$A18,Web!$G$2:$G$155,"Lỗi") -> 0 | E18: =COUNTIFS(Web!$A$2:$A$155,$A18,Web!$G$2:$G$155,"Bỏ qua") -> 0 | F18: =COUNTIFS(Web!$A$2:$A$155,$A18,Web!$G$2:$G$155,"Chưa test") -> 2 | G18: =IF(B18=0,0,(C18+D18+E18)/B18) -> 0
A19: Tổng Web | B19: =SUM(B6:B18) -> 154 | C19: =SUM(C6:C18) -> 0 | D19: =SUM(D6:D18) -> 2 | E19: =SUM(E6:E18) -> 0 | F19: =SUM(F6:F18) -> 141 | G19: =IF(B19=0,0,(C19+D19+E19)/B19) -> 0.012987013
A21: App
A22: Phân hệ | B22: Tổng | C22: Đạt | D22: Lỗi | E22: Bỏ qua | F22: Chưa test | G22: % Đã test
A23: Khung app | B23: =COUNTIF(App!$B$2:$B$122,A23) -> 9 | C23: =COUNTIFS(App!$B$2:$B$122,$A23,App!$L$2:$L$122,"Đạt") -> 0 | D23: =COUNTIFS(App!$B$2:$B$122,$A23,App!$L$2:$L$122,"Lỗi") -> 0 | E23: =COUNTIFS(App!$B$2:$B$122,$A23,App!$L$2:$L$122,"Bỏ qua") -> 0 | F23: =COUNTIFS(App!$B$2:$B$122,$A23,App!$L$2:$L$122,"Chưa test") -> 9 | G23: =IF(B23=0,0,(C23+D23+E23)/B23) -> 0
A24: Đăng nhập, khởi tạo | B24: =COUNTIF(App!$B$2:$B$122,A24) -> 3 | C24: =COUNTIFS(App!$B$2:$B$122,$A24,App!$L$2:$L$122,"Đạt") -> 0 | D24: =COUNTIFS(App!$B$2:$B$122,$A24,App!$L$2:$L$122,"Lỗi") -> 0 | E24: =COUNTIFS(App!$B$2:$B$122,$A24,App!$L$2:$L$122,"Bỏ qua") -> 0 | F24: =COUNTIFS(App!$B$2:$B$122,$A24,App!$L$2:$L$122,"Chưa test") -> 3 | G24: =IF(B24=0,0,(C24+D24+E24)/B24) -> 0
A25: Trang chủ | B25: =COUNTIF(App!$B$2:$B$122,A25) -> 19 | C25: =COUNTIFS(App!$B$2:$B$122,$A25,App!$L$2:$L$122,"Đạt") -> 0 | D25: =COUNTIFS(App!$B$2:$B$122,$A25,App!$L$2:$L$122,"Lỗi") -> 0 | E25: =COUNTIFS(App!$B$2:$B$122,$A25,App!$L$2:$L$122,"Bỏ qua") -> 0 | F25: =COUNTIFS(App!$B$2:$B$122,$A25,App!$L$2:$L$122,"Chưa test") -> 19 | G25: =IF(B25=0,0,(C25+D25+E25)/B25) -> 0
A26: Tìm kiếm | B26: =COUNTIF(App!$B$2:$B$122,A26) -> 2 | C26: =COUNTIFS(App!$B$2:$B$122,$A26,App!$L$2:$L$122,"Đạt") -> 0 | D26: =COUNTIFS(App!$B$2:$B$122,$A26,App!$L$2:$L$122,"Lỗi") -> 0 | E26: =COUNTIFS(App!$B$2:$B$122,$A26,App!$L$2:$L$122,"Bỏ qua") -> 0 | F26: =COUNTIFS(App!$B$2:$B$122,$A26,App!$L$2:$L$122,"Chưa test") -> 2 | G26: =IF(B26=0,0,(C26+D26+E26)/B26) -> 0
A27: Thu chi | B27: =COUNTIF(App!$B$2:$B$122,A27) -> 17 | C27: =COUNTIFS(App!$B$2:$B$122,$A27,App!$L$2:$L$122,"Đạt") -> 0 | D27: =COUNTIFS(App!$B$2:$B$122,$A27,App!$L$2:$L$122,"Lỗi") -> 0 | E27: =COUNTIFS(App!$B$2:$B$122,$A27,App!$L$2:$L$122,"Bỏ qua") -> 0 | F27: =COUNTIFS(App!$B$2:$B$122,$A27,App!$L$2:$L$122,"Chưa test") -> 17 | G27: =IF(B27=0,0,(C27+D27+E27)/B27) -> 0
A28: Kế toán bán hàng | B28: =COUNTIF(App!$B$2:$B$122,A28) -> 4 | C28: =COUNTIFS(App!$B$2:$B$122,$A28,App!$L$2:$L$122,"Đạt") -> 0 | D28: =COUNTIFS(App!$B$2:$B$122,$A28,App!$L$2:$L$122,"Lỗi") -> 0 | E28: =COUNTIFS(App!$B$2:$B$122,$A28,App!$L$2:$L$122,"Bỏ qua") -> 0 | F28: =COUNTIFS(App!$B$2:$B$122,$A28,App!$L$2:$L$122,"Chưa test") -> 4 | G28: =IF(B28=0,0,(C28+D28+E28)/B28) -> 0
A29: Kế toán mua hàng | B29: =COUNTIF(App!$B$2:$B$122,A29) -> 8 | C29: =COUNTIFS(App!$B$2:$B$122,$A29,App!$L$2:$L$122,"Đạt") -> 0 | D29: =COUNTIFS(App!$B$2:$B$122,$A29,App!$L$2:$L$122,"Lỗi") -> 0 | E29: =COUNTIFS(App!$B$2:$B$122,$A29,App!$L$2:$L$122,"Bỏ qua") -> 0 | F29: =COUNTIFS(App!$B$2:$B$122,$A29,App!$L$2:$L$122,"Chưa test") -> 8 | G29: =IF(B29=0,0,(C29+D29+E29)/B29) -> 0
A30: Kiểm kê | B30: =COUNTIF(App!$B$2:$B$122,A30) -> 5 | C30: =COUNTIFS(App!$B$2:$B$122,$A30,App!$L$2:$L$122,"Đạt") -> 0 | D30: =COUNTIFS(App!$B$2:$B$122,$A30,App!$L$2:$L$122,"Lỗi") -> 0 | E30: =COUNTIFS(App!$B$2:$B$122,$A30,App!$L$2:$L$122,"Bỏ qua") -> 0 | F30: =COUNTIFS(App!$B$2:$B$122,$A30,App!$L$2:$L$122,"Chưa test") -> 5 | G30: =IF(B30=0,0,(C30+D30+E30)/B30) -> 0
A31: Chi phí phân bổ | B31: =COUNTIF(App!$B$2:$B$122,A31) -> 6 | C31: =COUNTIFS(App!$B$2:$B$122,$A31,App!$L$2:$L$122,"Đạt") -> 0 | D31: =COUNTIFS(App!$B$2:$B$122,$A31,App!$L$2:$L$122,"Lỗi") -> 0 | E31: =COUNTIFS(App!$B$2:$B$122,$A31,App!$L$2:$L$122,"Bỏ qua") -> 0 | F31: =COUNTIFS(App!$B$2:$B$122,$A31,App!$L$2:$L$122,"Chưa test") -> 6 | G31: =IF(B31=0,0,(C31+D31+E31)/B31) -> 0
A32: Kê khai thuế | B32: =COUNTIF(App!$B$2:$B$122,A32) -> 4 | C32: =COUNTIFS(App!$B$2:$B$122,$A32,App!$L$2:$L$122,"Đạt") -> 0 | D32: =COUNTIFS(App!$B$2:$B$122,$A32,App!$L$2:$L$122,"Lỗi") -> 0 | E32: =COUNTIFS(App!$B$2:$B$122,$A32,App!$L$2:$L$122,"Bỏ qua") -> 0 | F32: =COUNTIFS(App!$B$2:$B$122,$A32,App!$L$2:$L$122,"Chưa test") -> 4 | G32: =IF(B32=0,0,(C32+D32+E32)/B32) -> 0
A33: Báo cáo | B33: =COUNTIF(App!$B$2:$B$122,A33) -> 17 | C33: =COUNTIFS(App!$B$2:$B$122,$A33,App!$L$2:$L$122,"Đạt") -> 0 | D33: =COUNTIFS(App!$B$2:$B$122,$A33,App!$L$2:$L$122,"Lỗi") -> 0 | E33: =COUNTIFS(App!$B$2:$B$122,$A33,App!$L$2:$L$122,"Bỏ qua") -> 0 | F33: =COUNTIFS(App!$B$2:$B$122,$A33,App!$L$2:$L$122,"Chưa test") -> 17 | G33: =IF(B33=0,0,(C33+D33+E33)/B33) -> 0
A34: Tab Khác | B34: =COUNTIF(App!$B$2:$B$122,A34) -> 23 | C34: =COUNTIFS(App!$B$2:$B$122,$A34,App!$L$2:$L$122,"Đạt") -> 0 | D34: =COUNTIFS(App!$B$2:$B$122,$A34,App!$L$2:$L$122,"Lỗi") -> 0 | E34: =COUNTIFS(App!$B$2:$B$122,$A34,App!$L$2:$L$122,"Bỏ qua") -> 0 | F34: =COUNTIFS(App!$B$2:$B$122,$A34,App!$L$2:$L$122,"Chưa test") -> 23 | G34: =IF(B34=0,0,(C34+D34+E34)/B34) -> 0
... A36: Doanh nghiệp TT58 | B36: =COUNTIF(App!$B$2:$B$122,A36) -> 1 | C36: =COUNTIFS(App!$B$2:$B$122,$A36,App!$L$2:$L$122,"Đạt") -> 0 | D36: =COUNTIFS(App!$B$2:$B$122,$A36,App!$L$2:$L$122,"Lỗi") -> 0 | E36: =COUNTIFS(App!$B$2:$B$122,$A36,App!$L$2:$L$122,"Bỏ qua") -> 0 | F36: =COUNTIFS(App!$B$2:$B$122,$A36,App!$L$2:$L$122,"Chưa test") -> 1 | G36: =IF(B36=0,0,(C36+D36+E36)/B36) -> 0
A37: Tổng App | B37: =SUM(B23:B36) -> 121 | C37: =SUM(C23:C36) -> 0 | D37: =SUM(D23:D36) -> 0 | E37: =SUM(E23:E36) -> 0 | F37: =SUM(F23:F36) -> 121 | G37: =IF(B37=0,0,(C37+D37+E37)/B37) -> 0
A39: Cả hai | B39: =B19+B37 -> 275 | C39: =C19+C37 -> 0 | D39: =D19+D37 -> 2 | E39: =E19+E37 -> 0 | F39: =F19+F37 -> 262 | G39: =IF(B39=0,0,(C39+D39+E39)/B39) -> 0.0072727273
A41: Cách dùng
A42: • Sheet Web: test trên máy tính (màn rộng từ 768px). Sheet App: test app điện thoại (màn rộng dưới 768px, hoặc chế độ điện thoại của trình duyệt).
A43: • Mỗi dòng là một ca kiểm. Làm theo cột Các bước, so với Kết quả mong đợi.
A44: • Chỉ điền các cột nền vàng: Kết quả thực tế, Trạng thái (Chưa test / Đạt / Lỗi / Bỏ qua), Người test, Ngày test, Ghi chú.
A45: • Lỗi thì ghi rõ hiện tượng ở Kết quả thực tế, rồi thêm việc mới vào docs/TIEN-DO.md.
...

Sheet Checklist
A1: Checklist test gói Standard
A2: Trạng thái tự lấy từ sheet Web, App: điền kết quả ở hai sheet đó, không điền ở đây. ☑ Đạt · ✗ Lỗi · – Bỏ qua · ☐ Chưa test.
A4: ✓ | B4: STT | C4: Nền tảng | D4: Màn hình | E4: Nội dung kiểm | F4: Mã TC | G4: Trạng thái | H4: Ưu tiên
A5: Khung app | G5: =COUNTIF(G6:G28,"Đạt")&"/23 đạt" -> 0/23 đạt
A6: =IF(G6="Đạt","☑",IF(G6="Lỗi","✗",IF(G6="Bỏ qua","–","☐"))) -> ☐ | B6: 1 | C6: Web | D6: Sidebar | E6: Sidebar chỉ hiện phân hệ của gói Standard | F6: W-KA-001 | G6: =IFERROR(INDEX(Web!$G:$G,MATCH(F6,Web!#REF!,0)),"") | H6: Cao
A7: =IF(G7="Đạt","☑",IF(G7="Lỗi","✗",IF(G7="Bỏ qua","–","☐"))) -> ☐ | B7: 2 | C7: Web | D7: Sidebar | E7: Phân hệ Kho đổi tên thành Kiểm kê | F7: W-KA-002 | G7: =IFERROR(INDEX(Web!$G:$G,MATCH(F7,Web!#REF!,0)),"") | H7: Trung bình
A8: =IF(G8="Đạt","☑",IF(G8="Lỗi","✗",IF(G8="Bỏ qua","–","☐"))) -> ☐ | B8: 3 | C8: Web | D8: Sidebar | E8: Tính năng ngoài gói ẩn hẳn, không có ổ khoá mời nâng cấp (QD22) | F8: W-KA-003 | G8: =IFERROR(INDEX(Web!$G:$G,MATCH(F8,Web!#REF!,0)),"") | H8: Cao
A9: =IF(G9="Đạt","☑",IF(G9="Lỗi","✗",IF(G9="Bỏ qua","–","☐"))) -> ☐ | B9: 4 | C9: Web | D9: Sidebar | E9: Bấm logo về Tổng quan | F9: W-KA-004 | G9: =IFERROR(INDEX(Web!$G:$G,MATCH(F9,Web!#REF!,0)),"") | H9: Trung bình
A10: =IF(G10="Đạt","☑",IF(G10="Lỗi","✗",IF(G10="Bỏ qua","–","☐"))) -> ☐ | B10: 5 | C10: Web | D10: Mở màn | E10: Vào /app luôn về Tổng quan, không có Bàn làm việc | F10: W-KA-005 | G10: =IFERROR(INDEX(Web!$G:$G,MATCH(F10,Web!#REF!,0)),"") | H10: Cao
A11: =IF(G11="Đạt","☑",IF(G11="Lỗi","✗",IF(G11="Bỏ qua","–","☐"))) -> ☐ | B11: 6 | C11: Web | D11: Mở màn | E11: Gõ đường dẫn màn ngoài gói thì về màn đầu phân hệ | F11: W-KA-006 | G11: =IFERROR(INDEX(Web!$G:$G,MATCH(F11,Web!#REF!,0)),"") | H11: Cao
A12: =IF(G12="Đạt","☑",IF(G12="Lỗi","✗",IF(G12="Bỏ qua","–","☐"))) -> ☐ | B12: 7 | C12: Web | D12: Thanh trên | E12: Đổi đơn vị kế toán | F12: W-KA-007 | G12: =IFERROR(INDEX(Web!$G:$G,MATCH(F12,Web!#REF!,0)),"") | H12: Trung bình
A13: =IF(G13="Đạt","☑",IF(G13="Lỗi","✗",IF(G13="Bỏ qua","–","☐"))) -> ☐ | B13: 8 | C13: Web | D13: Thanh trên | E13: Chọn cửa hàng làm việc lọc danh sách, báo cáo | F13: W-KA-008 | G13: =IFERROR(INDEX(Web!$G:$G,MATCH(F13,Web!#REF!,0)),"") | H13: Cao
A14: =IF(G14="Đạt","☑",IF(G14="Lỗi","✗",IF(G14="Bỏ qua","–","☐"))) -> ☐ | B14: 9 | C14: Web | D14: Thanh trên | E14: Đang xem Tất cả cửa hàng thì phải chọn cửa hàng trước khi lập phiếu | F14: W-KA-009 | G14: =IFERROR(INDEX(Web!$G:$G,MATCH(F14,Web!#REF!,0)),"") | H14: Cao
A15: =IF(G15="Đạt","☑",IF(G15="Lỗi","✗",IF(G15="Bỏ qua","–","☐"))) -> ☐ | B15: 10 | C15: Web | D15: Thanh trên | E15: Chip Dùng thử còn N ngày | F15: W-KA-010 | G15: =IFERROR(INDEX(Web!$G:$G,MATCH(F15,Web!#REF!,0)),"") | H15: Trung bình
A16: =IF(G16="Đạt","☑",IF(G16="Lỗi","✗",IF(G16="Bỏ qua","–","☐"))) -> ☐ | B16: 11 | C16: Web | D16: Thanh trên | E16: Gói Standard ẩn chuông thông báo, menu tài khoản ẩn Người dùng | F16: W-KA-011 | G16: =IFERROR(INDEX(Web!$G:$G,MATCH(F16,Web!#REF!,0)),"") | H16: Trung bình
A17: =IF(G17="Đạt","☑",IF(G17="Lỗi","✗",IF(G17="Bỏ qua","–","☐"))) -> ☐ | B17: 12 | C17: Web | D17: Tìm nhanh (Ctrl+K) | E17: Tìm màn bằng chữ không dấu | F17: W-KA-012 | G17: =IFERROR(INDEX(Web!$G:$G,MATCH(F17,Web!#REF!,0)),"") | H17: Trung bình
... A19: =IF(G19="Đạt","☑",IF(G19="Lỗi","✗",IF(G19="Bỏ qua","–","☐"))) -> ☐ | B19: 14 | C19: Web | D19: Thao tác nhanh | E19: Thao tác nhanh mặc định và tuỳ chỉnh | F19: W-KA-014 | G19: =IFERROR(INDEX(Web!$G:$G,MATCH(F19,Web!#REF!,0)),"") | H19: Trung bình
A20: =IF(G20="Đạt","☑",IF(G20="Lỗi","✗",IF(G20="Bỏ qua","–","☐"))) -> ☐ | B20: 15 | C20: App | D20: Thanh tab đáy | E20: 4 tab đáy và tab đang sáng | F20: A-KA-001 | G20: =IFERROR(INDEX(App!$L:$L,MATCH(F20,App!$A:$A,0)),"") -> Chưa test | H20: Cao
A21: =IF(G21="Đạt","☑",IF(G21="Lỗi","✗",IF(G21="Bỏ qua","–","☐"))) -> ☐ | B21: 16 | C21: App | D21: Thanh tab đáy | E21: Ẩn hiện khi cuộn | F21: A-KA-002 | G21: =IFERROR(INDEX(App!$L:$L,MATCH(F21,App!$A:$A,0)),"") -> Chưa test | H21: Trung bình
A22: =IF(G22="Đạt","☑",IF(G22="Lỗi","✗",IF(G22="Bỏ qua","–","☐"))) -> ☐ | B22: 17 | C22: App | D22: Thanh tab đáy | E22: Ẩn thanh tab ở màn cấp 2 | F22: A-KA-003 | G22: =IFERROR(INDEX(App!$L:$L,MATCH(F22,App!$A:$A,0)),"") -> Chưa test | H22: Cao
A23: =IF(G23="Đạt","☑",IF(G23="Lỗi","✗",IF(G23="Bỏ qua","–","☐"))) -> ☐ | B23: 18 | C23: App | D23: Thanh trên | E23: Chip chọn cửa hàng | F23: A-KA-004 | G23: =IFERROR(INDEX(App!$L:$L,MATCH(F23,App!$A:$A,0)),"") -> Chưa test | H23: Cao
A24: =IF(G24="Đạt","☑",IF(G24="Lỗi","✗",IF(G24="Bỏ qua","–","☐"))) -> ☐ | B24: 19 | C24: App | D24: Thanh trên | E24: Lập phiếu khi đang xem Tất cả cửa hàng | F24: A-KA-005 | G24: =IFERROR(INDEX(App!$L:$L,MATCH(F24,App!$A:$A,0)),"") -> Chưa test | H24: Cao
A25: =IF(G25="Đạt","☑",IF(G25="Lỗi","✗",IF(G25="Bỏ qua","–","☐"))) -> ☐ | B25: 20 | C25: App | D25: Thanh trên | E25: Nút Bộ lọc báo cáo | F25: A-KA-006 | G25: =IFERROR(INDEX(App!$L:$L,MATCH(F25,App!$A:$A,0)),"") -> Chưa test | H25: Trung bình
A26: =IF(G26="Đạt","☑",IF(G26="Lỗi","✗",IF(G26="Bỏ qua","–","☐"))) -> ☐ | B26: 21 | C26: App | D26: Chỉ dùng trên máy tính | E26: Màn chưa có bản điện thoại | F26: A-KA-007 | G26: =IFERROR(INDEX(App!$L:$L,MATCH(F26,App!$A:$A,0)),"") -> Chưa test | H26: Thấp
A27: =IF(G27="Đạt","☑",IF(G27="Lỗi","✗",IF(G27="Bỏ qua","–","☐"))) -> ☐ | B27: 22 | C27: App | D27: Đổi cỡ màn | E27: Chuyển qua lại web và app | F27: A-KA-008 | G27: =IFERROR(INDEX(App!$L:$L,MATCH(F27,App!$A:$A,0)),"") -> Chưa test | H27: Thấp
A28: =IF(G28="Đạt","☑",IF(G28="Lỗi","✗",IF(G28="Bỏ qua","–","☐"))) -> ☐ | B28: 23 | C28: App | D28: Ngoài gói | E28: Không hiện tính năng ngoài gói | F28: A-KA-009 | G28: =IFERROR(INDEX(App!$L:$L,MATCH(F28,App!$A:$A,0)),"") -> Chưa test | H28: Cao
A29: Đăng nhập, khởi tạo | G29: =COUNTIF(G30:G44,"Đạt")&"/15 đạt" -> 0/15 đạt
A30: =IF(G30="Đạt","☑",IF(G30="Lỗi","✗",IF(G30="Bỏ qua","–","☐"))) -> ☐ | B30: 24 | C30: Web | D30: Đăng nhập | E30: Kiểm tra ô đăng nhập | F30: W-KT-001 | G30: =IFERROR(INDEX(Web!$G:$G,MATCH(F30,Web!#REF!,0)),"") | H30: Cao
A31: =IF(G31="Đạt","☑",IF(G31="Lỗi","✗",IF(G31="Bỏ qua","–","☐"))) -> ☐ | B31: 25 | C31: Web | D31: Chọn đơn vị | E31: Thẻ đơn vị ghi đủ thông tin | F31: W-KT-002 | G31: =IFERROR(INDEX(Web!$G:$G,MATCH(F31,Web!#REF!,0)),"") | H31: Trung bình
A32: =IF(G32="Đạt","☑",IF(G32="Lỗi","✗",IF(G32="Bỏ qua","–","☐"))) -> ☐ | B32: 26 | C32: Web | D32: Mở từ FABi | E32: Đi hết 4 màn mở từ FABi | F32: W-KT-003 | G32: =IFERROR(INDEX(Web!$G:$G,MATCH(F32,Web!#REF!,0)),"") | H32: Cao
A33: =IF(G33="Đạt","☑",IF(G33="Lỗi","✗",IF(G33="Bỏ qua","–","☐"))) -> ☐ | B33: 27 | C33: Web | D33: Mở từ FABi | E33: Phải chọn ít nhất 1 cửa hàng dùng thử | F33: W-KT-004 | G33: =IFERROR(INDEX(Web!$G:$G,MATCH(F33,Web!#REF!,0)),"") | H33: Trung bình
A34: =IF(G34="Đạt","☑",IF(G34="Lỗi","✗",IF(G34="Bỏ qua","–","☐"))) -> ☐ | B34: 28 | C34: Web | D34: Popup khởi tạo | E34: Popup bắt buộc, không đóng được, nhớ tiến độ | F34: W-KT-005 | G34: =IFERROR(INDEX(Web!$G:$G,MATCH(F34,Web!#REF!,0)),"") | H34: Cao
A35: =IF(G35="Đạt","☑",IF(G35="Lỗi","✗",IF(G35="Bỏ qua","–","☐"))) -> ☐ | B35: 29 | C35: Web | D35: Popup khởi tạo › B1 Loại hình | E35: Hộ kinh doanh: gợi ý nhóm theo doanh thu FABi | F35: W-KT-006 | G35: =IFERROR(INDEX(Web!$G:$G,MATCH(F35,Web!#REF!,0)),"") | H35: Cao
A36: =IF(G36="Đạt","☑",IF(G36="Lỗi","✗",IF(G36="Bỏ qua","–","☐"))) -> ☐ | B36: 30 | C36: Web | D36: Popup khởi tạo › B1 Loại hình | E36: Cảnh báo khi kê khai thuế không có ở gói Standard | F36: W-KT-007 | G36: =IFERROR(INDEX(Web!$G:$G,MATCH(F36,Web!#REF!,0)),"") | H36: Trung bình
A37: =IF(G37="Đạt","☑",IF(G37="Lỗi","✗",IF(G37="Bỏ qua","–","☐"))) -> ☐ | B37: 31 | C37: Web | D37: Popup khởi tạo › B2 Thông tin | E37: Bắt buộc nhập theo loại hình | F37: W-KT-008 | G37: =IFERROR(INDEX(Web!$G:$G,MATCH(F37,Web!#REF!,0)),"") | H37: Cao
A38: =IF(G38="Đạt","☑",IF(G38="Lỗi","✗",IF(G38="Bỏ qua","–","☐"))) -> ☐ | B38: 32 | C38: Web | D38: Popup khởi tạo › B2 Thông tin | E38: Tra cứu MST, ngày đầu năm tài chính | F38: W-KT-009 | G38: =IFERROR(INDEX(Web!$G:$G,MATCH(F38,Web!#REF!,0)),"") | H38: Trung bình
A39: =IF(G39="Đạt","☑",IF(G39="Lỗi","✗",IF(G39="Bỏ qua","–","☐"))) -> ☐ | B39: 33 | C39: Web | D39: Popup khởi tạo › B3 Cửa hàng | E39: Chọn cửa hàng lên sổ, cửa hàng chính | F39: W-KT-010 | G39: =IFERROR(INDEX(Web!$G:$G,MATCH(F39,Web!#REF!,0)),"") | H39: Cao
A40: =IF(G40="Đạt","☑",IF(G40="Lỗi","✗",IF(G40="Bỏ qua","–","☐"))) -> ☐ | B40: 34 | C40: Web | D40: Popup khởi tạo › Lấy dữ liệu | E40: Lấy dữ liệu FABi và bắt đầu làm việc | F40: W-KT-011 | G40: =IFERROR(INDEX(Web!$G:$G,MATCH(F40,Web!#REF!,0)),"") | H40: Cao
A41: =IF(G41="Đạt","☑",IF(G41="Lỗi","✗",IF(G41="Bỏ qua","–","☐"))) -> ☐ | B41: 35 | C41: Web | D41: Popup khởi tạo › Lấy dữ liệu | E41: Doanh thu FABi vào Xuất bán POS | F41: W-KT-012 | G41: =IFERROR(INDEX(Web!$G:$G,MATCH(F41,Web!#REF!,0)),"") | H41: Trung bình
A42: =IF(G42="Đạt","☑",IF(G42="Lỗi","✗",IF(G42="Bỏ qua","–","☐"))) -> ☐ | B42: 36 | C42: App | D42: Đăng nhập | E42: Đăng nhập trên điện thoại | F42: A-KT-001 | G42: =IFERROR(INDEX(App!$L:$L,MATCH(F42,App!$A:$A,0)),"") -> Chưa test | H42: Cao
...

Sheet Web
A1: Phân hệ | B1: Màn hình | C1: Mục đích | D1: Các bước | E1: Kết quả mong đợi | F1: Kết quả thực tế | H1: Người test | I1: Ngày test | J1: Ghi chú
A2: Khung app | B2: Sidebar | C2: Sidebar chỉ hiện phân hệ của gói Standard | D2: 1. Vào /app 2. Xem sidebar | E2: Hiện: Trang chủ, Thu chi, Kế toán bán hàng, Kế toán mua hàng, Kiểm kê, Chi phí phân bổ, Kê khai thuế, Báo cáo, Danh mục, Hệ thống. Không có Tổng hợp, Tiện ích, TSCĐ, Giá thành | G2: Chưa test
A3: Khung app | B3: Sidebar | C3: Phân hệ Kho đổi tên thành Kiểm kê | D3: 1. Xem sidebar 2. Bấm Kiểm kê | E3: Tên phân hệ là Kiểm kê, mở tab Kiểm kê số lượng | G3: Chưa test
A4: Khung app | B4: Sidebar | C4: Tính năng ngoài gói ẩn hẳn, không có ổ khoá mời nâng cấp (QD22) | D4: 1. Mở lần lượt từng phân hệ 2. Xem các tab | E4: Không tab, nút, mục nào có biểu tượng khoá hay chữ Nâng cấp | G4: Chưa test
A5: Khung app | B5: Sidebar | C5: Bấm logo về Tổng quan | D5: 1. Mở một màn bất kỳ, vd Danh mục hàng hoá 2. Bấm logo | E5: Về Trang chủ › Tổng quan | G5: Chưa test
A6: Khung app | B6: Mở màn | C6: Vào /app luôn về Tổng quan, không có Bàn làm việc | D6: 1. Đăng nhập lần lượt bằng các vai trò mẫu 2. Vào /app | E6: Mọi vai trò mở Tổng quan, không có màn Bàn làm việc | G6: Chưa test
A7: Khung app | B7: Mở màn | C7: Gõ đường dẫn màn ngoài gói thì về màn đầu phân hệ | D7: 1. Gõ thẳng đường dẫn /app/he-thong/nguoi-dung 2. Gõ /app/tong-hop/... một màn Tổng hợp | E7: Chuyển về màn đầu của phân hệ, không hiện trang Nâng cấp, không hiện thẻ Chưa mở bán | G7: Chưa test
A8: Khung app | B8: Thanh trên | C8: Đổi đơn vị kế toán | D8: 1. Bấm ô chọn đơn vị 2. Chọn đơn vị khác | E8: Đổi gói theo đơn vị mới, cửa hàng về Tất cả cửa hàng. Có mục Thêm đơn vị kế toán | G8: Chưa test
A9: Khung app | B9: Thanh trên | C9: Chọn cửa hàng làm việc lọc danh sách, báo cáo | D9: 1. Chọn cửa hàng A 2. Mở danh sách phiếu thu chi 3. Đổi sang Tất cả cửa hàng | E9: Bước 2 chỉ có phiếu của cửa hàng A; bước 3 hiện gộp mọi cửa hàng | G9: Chưa test
A10: Khung app | B10: Thanh trên | C10: Đang xem Tất cả cửa hàng thì phải chọn cửa hàng trước khi lập phiếu | D10: 1. Chọn Tất cả cửa hàng 2. Bấm Thêm phiếu thu | E10: Hiện hộp chọn cửa hàng. Chọn xong mới mở form phiếu, form gắn cửa hàng vừa chọn | G10: Chưa test
A11: Khung app | B11: Thanh trên | C11: Chip Dùng thử còn N ngày | D11: 1. Đơn vị tạo từ FABi 2. Xem thanh trên 3. Đổi ngày tạo để còn ≤ 7 ngày | E11: Hiện Dùng thử · còn N ngày, tính 30 ngày từ ngày tạo; còn từ 7 ngày trở xuống thì tô màu cảnh báo | G11: Chưa test
A12: Khung app | B12: Thanh trên | C12: Gói Standard ẩn chuông thông báo, menu tài khoản ẩn Người dùng | D12: 1. Xem thanh trên 2. Mở menu tài khoản | E12: Không có chuông thông báo, menu không có mục Người dùng | G12: Chưa test
A13: Khung app | B13: Tìm nhanh (Ctrl+K) | C13: Tìm màn bằng chữ không dấu | D13: 1. Bấm Ctrl+K 2. Gõ 'kiem ke' | E13: Ra Kiểm kê số lượng, Báo cáo kiểm kê; bấm kết quả mở đúng màn | G13: Chưa test
... A93: Kế toán bán hàng | B93: Sổ doanh thu 3.2.5 | C93: Mẫu sổ theo chế độ, cách tính thuế | D93: 1. HKD nhóm 1: mở sổ 2. HKD nhóm 2 theo % doanh thu 3. HKD theo lợi nhuận 4. Doanh nghiệp TT58 | E93: Nhóm 1: mẫu S1a-HKD. Theo doanh thu: S2a-HKD. Theo lợi nhuận: không có sổ. TT58: chỉ S1-DNSN | G93: Chưa test
A94: Kế toán mua hàng | B94: Quy trình | C94: Sơ đồ quy trình mua hàng | D94: 1. Mở tab Quy trình | E94: Bấm từng bước mở đúng màn
A95: Kế toán mua hàng | B95: Phiếu mua hàng 4.1.1 | C95: Thêm phiếu bất kỳ | D95: Thêm phiếu điền đầy đủ thông tin các trường | E95: Ở ngoài lọc tất cả cửa hàng thì thêm mới cần chọn cửa hàng, đã chọn cửa hàng thì thêm mới vào thẳng phiếu cho cửa hàng đó luôn Chọn đối tượng các tt mst hay địa chỉ đều tự nhảy theo Các màn đối tượng, mã hàng đều thêm được ngay tại màn hình mua hàng Search thông tin theo mã hoặc tên đều được Mã đã bỏ active không thêm được ở chứng từ Với phương pháp tính thuế GTGT theo tỷ lệ doanh thu, thì giá trị nhập kho có cộng thuế GTGT | G95: Lỗi
A96: Kế toán mua hàng | B96: Phiếu mua hàng 4.1.1 | C96: Sửa chứng từ | D96: Check sửa all thông tin | E96: Khi sửa lưu lại là thông tin đã sửa ở cả chi tiết và danh sách. Check cả lịch sử của phiếu đã lưu lại lịch sử chưa | G96: Lỗi
A97: Kế toán mua hàng | B97: Phiếu mua hàng 4.1.1 | C97: Lập phiếu mua còn nợ | D97: 1. Thêm phiếu 2. Chọn NCC, kho, ngày, 2 dòng hàng 3. Không tích Đã thanh toán, lưu | E97: Số phiếu tiền tố MH; một kho ở đầu phiếu; có nút Thanh toán; công nợ NCC tăng
A98: Kế toán mua hàng | B98: Phiếu mua hàng 4.1.1 | C98: Đã thanh toán sinh phiếu chi | D98: 1. Lập phiếu, tích Đã thanh toán, chọn quỹ tiền mặt, lưu 2. Làm lại với tài khoản ngân hàng | E98: Tự lập phiếu chi (hoặc UNC) lý do Thanh toán công nợ NCC, tham chiếu hai chiều mở qua lại được
A99: Kế toán mua hàng | B99: Phiếu mua hàng 4.1.1 | C99: Nhận kèm hoá đơn | D99: 1. Tích Nhận kèm hoá đơn 2. Để trống số, ký hiệu, ngày hoá đơn, lưu | E99: Báo thiếu, không lưu
A100: Kế toán mua hàng | B100: Phiếu mua hàng 4.1.1 | C100: HKD không khấu trừ thuế đầu vào | D100: 1. HKD lập phiếu có thuế GTGT 2. Xem giá trị nhập kho | E100: Giá trị nhập kho = tiền trước thuế + thuế
A101: Kế toán mua hàng | B101: Phiếu mua hàng 4.1.1 | C101: Thanh toán phiếu còn nợ | D101: 1. Mở phiếu còn nợ, bấm Thanh toán 2. Nhập 0 3. Nhập lớn hơn số còn phải trả 4. Nhập hợp lệ | E101: Bước 2, 3 báo lỗi; bước 4 sinh phiếu chi, số còn nợ giảm
A102: Kế toán mua hàng | B102: Phiếu mua hàng 4.1.1 | C102: Phiếu đã trả, tháng khoá sổ không sửa | D102: 1. Mở phiếu đã thanh toán, bấm Sửa 2. Mở phiếu tháng đã khoá | E102: Không sửa được
A103: Kế toán mua hàng | B103: Phiếu mua hàng 4.1.1 | C103: Bắt buộc trên phiếu | D103: 1. Lưu thiếu NCC, kho hoặc không có dòng hàng 2. Số lượng 0 | E103: Báo lỗi, không lưu
A104: Kế toán mua hàng | B104: Công nợ NCC 4.2.3 | C104: Công thức công nợ | D104: 1. Mở báo cáo kỳ tháng 10 2. Kiểm một NCC | E104: I Nợ đầu + II Tiền mua − III Trả hàng − IV Thanh toán = V Nợ cuối; tổng khớp trang chủ
A105: Kế toán mua hàng | B105: Công nợ NCC 4.2.3 | C105: Xem gộp, lịch sử công nợ, thanh toán ngay | D105: 1. Chọn Tất cả cửa hàng 2. Bấm tên NCC 3. Bấm Thanh toán ngay | E105: Dưới mỗi NCC là từng cửa hàng. Lịch sử công nợ cộng khớp dòng báo cáo. Thanh toán ngay hỏi tiền mặt hay ngân hàng rồi mở phiếu chi
A106: Kế toán mua hàng | B106: Bảng kê chi tiết mua hàng | C106: Bảng kê khớp phiếu | D106: 1. Mở báo cáo 2. So một phiếu 4.1.1 | E106: Mỗi mặt hàng của phiếu một dòng, tổng khớp
A107: Kiểm kê | B107: Quy trình | C107: Sơ đồ quy trình kiểm kê | D107: 1. Mở tab Quy trình | E107: Bấm từng bước mở đúng màn | G107: Chưa test
A108: Kiểm kê | B108: Phiếu kiểm kê 5.1.10 | C108: Lập phiếu kiểm kê theo số lượng | D108: 1. Thêm phiếu, chọn kho 2. Nhập tồn thực tế vài dòng, để trống vài dòng 3. Lưu | E108: Bảng có tồn hệ thống, thực tế, chênh lệch theo số lượng, không có tiền. Ô trống lấy tồn hệ thống (chênh 0) | G108: Chưa test
A109: Kiểm kê | B109: Phiếu kiểm kê 5.1.10 | C109: Sinh phiếu điều chỉnh | D109: 1. Lưu phiếu KK2610-0256 có dòng thiếu và dòng thừa 2. Mở tab Xuất, nhập điều chỉnh | E109: Có XDC2610-0256 cho phần thiếu, NDC2610-0256 cho phần thừa | G109: Chưa test
A110: Kiểm kê | B110: Phiếu kiểm kê 5.1.10 | C110: Sửa, xoá phiếu đã sinh điều chỉnh | D110: 1. Mở phiếu đã sinh điều chỉnh, bấm Sửa 2. Xoá phiếu | E110: Không sửa được. Xoá thì xoá luôn hai phiếu điều chỉnh | G110: Chưa test
A111: Kiểm kê | B111: Xuất, nhập điều chỉnh | C111: Chỉ xem, không có giá trị | D111: 1. Mở tab 2. Mở một phiếu | E111: Không có Thêm, Sửa; không hiện giá trị tiền | G111: Chưa test
A112: Kiểm kê | B112: Xuất nhập tồn 5.2.3 | C112: Chỉ số lượng, khớp kiểm kê | D112: 1. Mở báo cáo 2. Đổi cửa hàng trên thanh trên | E112: Cột đầu kỳ, nhập, xuất, cuối kỳ chỉ số lượng, không giá trị, không dòng tổng. Kho đổi theo cửa hàng | G112: Chưa test
A113: Kiểm kê | B113: Xuất nhập tồn 5.2.3 | C113: Mở Thẻ kho 5.2.1 | D113: 1. Bấm mã hàng 2. Xem danh sách báo cáo | E113: Mở Thẻ kho cùng hàng, kho, kỳ. Thẻ kho không có trong danh sách báo cáo | G113: Chưa test
A114: Kiểm kê | B114: Tổng hợp nhập kho 5.2.9 | C114: Tổng hợp nhập khớp phiếu mua, nhập điều chỉnh | D114: 1. Mở báo cáo kỳ tháng 10 | E114: Khớp tổng số lượng phiếu nhập trong kỳ | G114: Chưa test
A115: Kiểm kê | B115: Chi tiết nhập kho 5.2.10 | C115: Chi tiết nhập kho | D115: 1. Mở báo cáo 2. Bấm số chứng từ | E115: Mỗi dòng nhập một dòng; bấm mở phiếu | G115: Chưa test
A116: Kiểm kê | B116: Báo cáo kiểm kê 5.2.15 | C116: Báo cáo kiểm kê khớp phiếu | D116: 1. Mở báo cáo tháng có phiếu kiểm kê | E116: Thiếu, thừa theo số lượng khớp phiếu và khối Hao hụt trang chủ | G116: Chưa test
A117: Kiểm kê | B117: Kiểm kê (chung) | C117: Báo cáo kho ẩn | D117: 1. Mở tab Báo cáo | E117: Không có Tổng hợp xuất kho, Chi tiết xuất kho | G117: Chưa test
A118: Chi phí phân bổ | B118: Quy trình | C118: Sơ đồ quy trình chi phí phân bổ | D118: 1. Mở tab Quy trình | E118: Bấm từng bước mở đúng màn | G118: Chưa test
... A155: Doanh nghiệp TT58 | B155: Báo cáo | C155: Sổ theo chế độ TT58 | D155: 1. Mở Tất cả báo cáo | E155: Sổ doanh thu chỉ S1-DNSN, không có S1a, S2a-HKD | G155: Chưa test

Sheet App
A1: Mã TC | B1: Phân hệ | C1: Màn hình | D1: Vào từ | E1: Loại kiểm | F1: Mục đích | G1: Tiền điều kiện | H1: Các bước | I1: Kết quả mong đợi | J1: Ưu tiên | K1: Kết quả thực tế | L1: Trạng thái | M1: Người test | N1: Ngày test | O1: Ghi chú
A2: A-KA-001 | B2: Khung app | C2: Thanh tab đáy | D2: Mọi màn gốc | E2: Hiển thị | F2: 4 tab đáy và tab đang sáng | G2: App điện thoại (màn rộng dưới 768px), đơn vị Phố Mây gói Standard, hộ kinh doanh TT152 | H2: 1. Mở app 2. Bấm lần lượt Trang chủ, Nghiệp vụ, Báo cáo, Khác 3. Mở một màn Danh mục, một màn Hệ thống | I2: Có 4 tab, tab đang mở sáng đúng. Màn Danh mục, Hệ thống thuộc tab Khác | J2: Cao | L2: Chưa test
A3: A-KA-002 | B3: Khung app | C3: Thanh tab đáy | D3: Mọi màn gốc | E3: Hiển thị | F3: Ẩn hiện khi cuộn | G3: App điện thoại (màn rộng dưới 768px), đơn vị Phố Mây gói Standard, hộ kinh doanh TT152 | H3: 1. Ở Trang chủ cuộn xuống 2. Cuộn lên 3. Cuộn về sát đầu trang 4. Đổi sang màn khác | I3: Cuộn xuống thì thanh trượt ẩn; cuộn lên thì hiện; sát đầu trang luôn hiện; đổi màn thì hiện lại | J3: Trung bình | L3: Chưa test
A4: A-KA-003 | B4: Khung app | C4: Thanh tab đáy | D4: Màn cấp 2 | E4: Hiển thị | F4: Ẩn thanh tab ở màn cấp 2 | G4: App điện thoại (màn rộng dưới 768px), đơn vị Phố Mây gói Standard, hộ kinh doanh TT152 | H4: 1. Mở xem một phiếu 2. Mở một báo cáo 3. Mở Lịch sử thu chi, Chi phí hoạt động 4. Mở một màn con Danh mục, Hệ thống, Khoá sổ | I4: Các màn này không có thanh tab đáy, có nút Quay lại trên đầu | J4: Cao | L4: Chưa test
A5: A-KA-004 | B5: Khung app | C5: Thanh trên | D5: Màn danh sách | E5: Chức năng | F5: Chip chọn cửa hàng | G5: App điện thoại (màn rộng dưới 768px), đơn vị Phố Mây gói Standard, hộ kinh doanh TT152 | H5: 1. Mở danh sách phiếu thu chi 2. Bấm chip cửa hàng 3. Chọn Tất cả cửa hàng, rồi chọn cửa hàng A | I5: Có mục Tất cả cửa hàng kèm dòng 'Chỉ xem gộp, chưa lập chứng từ'. Chọn A thì danh sách chỉ còn phiếu của A | J5: Cao | L5: Chưa test
A6: A-KA-005 | B6: Khung app | C6: Thanh trên | D6: Màn danh sách | E6: Ràng buộc | F6: Lập phiếu khi đang xem Tất cả cửa hàng | G6: App điện thoại (màn rộng dưới 768px), đơn vị Phố Mây gói Standard, hộ kinh doanh TT152 | H6: 1. Chọn Tất cả cửa hàng (chưa từng chọn cửa hàng nào) 2. Bấm + lập phiếu 3. Bấm Đóng ở tấm chọn cửa hàng 4. Lặp lại, lần này chọn cửa hàng A | I6: Hiện tấm chọn cửa hàng trước. Đóng thì quay về trang trước. Chọn A thì mở form gắn cửa hàng A. Lần sau đã nhớ cửa hàng thì tự chọn cửa hàng đó | J6: Cao | L6: Chưa test
A7: A-KA-006 | B7: Khung app | C7: Thanh trên | D7: Màn báo cáo | E7: Hiển thị | F7: Nút Bộ lọc báo cáo | G7: App điện thoại (màn rộng dưới 768px), đơn vị Phố Mây gói Standard, hộ kinh doanh TT152 | H7: 1. Mở một báo cáo | I7: Góc phải thanh trên là nút phễu Bộ lọc báo cáo thay cho chip cửa hàng | J7: Trung bình | L7: Chưa test
A8: A-KA-007 | B8: Khung app | C8: Chỉ dùng trên máy tính | D8: Gõ đường dẫn | E8: Hiển thị | F8: Màn chưa có bản điện thoại | G8: App điện thoại (màn rộng dưới 768px), đơn vị Phố Mây gói Standard, hộ kinh doanh TT152 | H8: 1. Gõ đường dẫn một màn chỉ có trên web 2. Bấm nút về Nghiệp vụ | I8: Hiện 'Chỉ dùng trên máy tính'; nút đưa về tab Nghiệp vụ | J8: Thấp | L8: Chưa test
A9: A-KA-008 | B9: Khung app | C9: Đổi cỡ màn | D9: Mọi màn | E9: Hiển thị | F9: Chuyển qua lại web và app | G9: App điện thoại (màn rộng dưới 768px), đơn vị Phố Mây gói Standard, hộ kinh doanh TT152 | H9: 1. Mở màn ở bề rộng ≥ 768px 2. Thu nhỏ dưới 768px 3. Mở rộng lại | I9: Dưới 768px dùng giao diện app, từ 768px dùng giao diện web, không mất dữ liệu đang xem | J9: Thấp | L9: Chưa test
A10: A-KA-009 | B10: Khung app | C10: Ngoài gói | D10: Mọi tab | E10: Hiển thị | F10: Không hiện tính năng ngoài gói | G10: App điện thoại (màn rộng dưới 768px), đơn vị Phố Mây gói Standard, hộ kinh doanh TT152 | H10: 1. Xem tab Nghiệp vụ, Báo cáo, Khác | I10: Không có Tổng hợp, Tiện ích, TSCĐ, Giá thành, Người dùng, Phân quyền, Danh mục tài khoản, Tờ khai GTGT, Nhập/xuất kho, Điều chuyển; không có biểu tượng khoá mời nâng cấp | J10: Cao | L10: Chưa test
A11: A-KT-001 | B11: Đăng nhập, khởi tạo | C11: Đăng nhập | D11: Mở app | E11: Ràng buộc | F11: Đăng nhập trên điện thoại | G11: App điện thoại, chưa đăng nhập | H11: 1. Để trống tài khoản 2. Mật khẩu dưới 6 ký tự 3. Nhập đúng | I11: Bước 1, 2 báo lỗi; bước 3 vào chọn đơn vị | J11: Cao | L11: Chưa test
A12: A-KT-002 | B12: Đăng nhập, khởi tạo | C12: Mở từ FABi (điện thoại) | D12: Thử mở từ FABi | E12: Hiển thị | F12: 4 màn mở từ FABi trên điện thoại | G12: App điện thoại, đã đăng nhập | H12: 1. Bấm Thử mở từ FABi 2. Đi qua Chào, Giao diện kế toán, Chọn cửa hàng 3. Bấm Dùng thử | I12: Màn Giao diện dùng ảnh trang chủ app đánh số 1–5; Quay lại và Dùng thử ghim đáy thành 2 ô; vào app, popup khởi tạo hiện đè | J12: Cao | L12: Chưa test
A13: A-KT-003 | B13: Đăng nhập, khởi tạo | C13: Popup khởi tạo (điện thoại) | D13: Sau Dùng thử | E13: Hiển thị | F13: Popup khởi tạo vừa màn điện thoại | G13: Vừa tạo đơn vị từ FABi trên điện thoại | H13: 1. Đi hết 3 bước và Lấy dữ liệu | I13: Hàng nút Quay lại, Tiếp tục ghim sát đáy, không phải cuộn mới thấy; nội dung không tràn ngang | J13: Trung bình | L13: Chưa test
... A122: A-DN-001 | B122: Doanh nghiệp TT58 | C122: Toàn app | D122: Mọi tab | E122: Tích hợp | F122: Doanh nghiệp gói Standard trên app | G122: App điện thoại, đơn vị doanh nghiệp gói Standard | H122: 1. Đổi sang đơn vị doanh nghiệp gói Standard 2. Lập phiếu thu, mua, kiểm kê 3. Mở tab Báo cáo | I122: Không Nợ/Có, không Ghi sổ; sổ doanh thu chỉ S1-DNSN | J122: Cao | L122: Chưa test
